<?xml version="1.0"?>
<robot xmlns:xacro="http://www.ros.org/wiki/xacro" name="ela2">


  <xacro:include filename="$(find ela2_arms)/urdf/ela2_gazebo.xacro"/>

  <xacro:include filename="$(find ela2_arms)/urdf/ela2_ros2_control.xacro"/>

  <xacro:property name="PI" value="3.14159"/>
  <xacro:property name="effort" value="30.0"/>
  <xacro:property name="velocity" value="10.0"/>


  <xacro:macro name="default_transmission" params="number joint_name">
      <transmission name="transmission_${number}">
          <plugin>transmission_interface/SimpleTransmission</plugin>
          <actuator name="motor_${number}" role="actuator1">
              <hardwareInterface>hardware_interface/PositionJointInterface</hardwareInterface>
          </actuator>
          <joint name="${joint_name}" role="joint1">
              <hardwareInterface>hardware_interface/PositionJointInterface</hardwareInterface>
              <mechanical_reduction>1.0</mechanical_reduction>
          </joint>
      </transmission>
  </xacro:macro>






  <!-- World link (placeholder) -->
  <link name="world"/>

  <!-- Base link -->
  <link name="base_link">
    <visual>
      <origin xyz="0 0 0" rpy="0 0 0"/>
      <geometry>
        <mesh filename="package://ela2_arms/meshes/base.stl" scale="0.01 0.01 0.01"/>
      </geometry>
    </visual>

  </link>

  <!-- Virtual Joint (base link to world) -->
  <joint name="virtual_joint" type="fixed">
    <parent link="world"/>
    <child link="base_link"/>
    <origin xyz="0 0 0" rpy="0 0 0"/>
  </joint>

  <!-- ====================== Chest  ======================  -->
  <link name="chest">
    <visual>
      <origin xyz="0 0 -4.65" rpy="0 0 0"/>
      <geometry>
        <mesh filename="package://ela2_arms/meshes/chest.stl" scale="0.01 0.01 0.01"/>
      </geometry>
    </visual>
    <collision>
      <origin xyz="0 0 -4.65" rpy="0 0 0"/>
      <geometry>
        <box size="0.2 0.1 0.1"/>
      </geometry>
    </collision>
    <inertial>
      <origin xyz="0 0 0" rpy="0 0 0"/>
      <mass value="1.0"/>
      <inertia ixx="1" ixy="0.0" ixz="0.0" iyy="1" iyz="0.0" izz="1"/>
    </inertial>
  </link>

  <!-- Chest joint (fixed to base link) -->
  <joint name="base_joint" type="fixed">
    <parent link="base_link"/>
    <child link="chest"/>
    <origin xyz="0 0 5.57" rpy="0 0 0"/>
  </joint>

  <!--====================== Left Upper Arm ======================-->
  <link name="left_upper_arm_x">
    <visual>
      <origin xyz="1 -0.4 -4.5661" rpy="0 0 0"/>
      <geometry>
        <mesh filename="package://ela2_arms/meshes/Left_Upper_Arm.stl" scale="0.01 0.01 0.01"/>
      </geometry>
    </visual>
    <collision>
      <origin xyz="1 -0.4 -4.5661" rpy="0 0 0"/>
      <geometry>
        <box size="0.1 0.1 0.1"/>
      </geometry>
    </collision>
    <inertial>
      <origin xyz="0 0 0" rpy="0 0 0"/>
      <mass value="1.0"/>
      <inertia ixx="1" ixy="0.0" ixz="0.0" iyy="1" iyz="0.0" izz="1"/>
    </inertial>
  </link>

  <link name="left_upper_arm_y">
    <visual>
      <origin xyz="2 -0.4 0" rpy="0 0 0"/>
      <geometry>
        <box size="0.01 0.01 0.01"/>
      </geometry>
    </visual>
    <collision>
      <origin xyz="2 -0.4 0" rpy="0 0 0"/>
      <geometry>
        <box size="0.1 0.1 0.1"/>
      </geometry>
    </collision>
    <inertial>
      <origin xyz="0 0 0" rpy="0 0 0"/>
      <mass value="1.0"/>
      <inertia ixx="1" ixy="0.0" ixz="0.0" iyy="1" iyz="0.0" izz="1"/>
    </inertial>
  </link>

  <joint name="left_upper_arm_y_joint" type="revolute">
    <parent link="chest"/>
    <child link="left_upper_arm_y"/>
    <axis xyz="0 1 0"/>
    <origin xyz="-1.04 0.4 0" rpy="0 0 0"/>
    <limit lower="0" upper="${PI/2}" effort="${effort}" velocity="${velocity}"/>
  </joint>

  <joint name="left_upper_arm_x_joint" type="revolute">
    <parent link="left_upper_arm_y"/>
    <child link="left_upper_arm_x"/>
    <axis xyz="1 0 0"/>
    <origin xyz="0 0 0" rpy="0 0 0"/>
    <limit lower="-${1.197}" upper="${0.704}" effort="${effort}" velocity="${velocity}"/>
  </joint>
  
  <!--====================== Left Forearm ======================-->
  <link name="left_forearm_x">
    <visual>
      <origin xyz="1.25 -0.4 -2.5661" rpy="0 0 0"/>
      <geometry>
        <mesh filename="package://ela2_arms/meshes/Left_Forearm.stl" scale="0.01 0.01 0.01"/>
      </geometry>
    </visual>
    <collision>
      <origin xyz="1.25 -0.4 -2.5661" rpy="0 0 0"/>
      <geometry>
        <box size="0.1 0.1 0.1"/>
      </geometry>
    </collision>
    <inertial>
      <origin xyz="0 0 0" rpy="0 0 0"/>
      <mass value="1.0"/>
      <inertia ixx="1" ixy="0.0" ixz="0.0" iyy="1" iyz="0.0" izz="1"/>
    </inertial>
  </link>

  <link name="left_forearm_z">
    <visual>
      <origin xyz="0 0 0" rpy="0 0 0"/>
      <geometry>
        <box size="0.01 0.01 0.01"/>
      </geometry>
    </visual>
    <collision>
      <origin xyz="0 0 0" rpy="0 0 0"/>
      <geometry>
        <box size="0.1 0.1 0.1"/>
      </geometry>
    </collision>
    <inertial>
      <origin xyz="0 0 0" rpy="0 0 0"/>
      <mass value="1.0"/>
      <inertia ixx="1" ixy="0.0" ixz="0.0" iyy="1" iyz="0.0" izz="1"/>
    </inertial>
  </link>

  <joint name="left_forearm_z_joint" type="revolute">
    <parent link="left_upper_arm_x"/>
    <child link="left_forearm_z"/>
    <axis xyz="0 0 1"/>
    <origin xyz="-0.25 -0.04 -2" rpy="0 0 0"/>
    <limit lower="-${PI/2}" upper="${PI/2}" effort="${effort}" velocity="${velocity}"/>
  </joint>

  <joint name="left_forearm_x_joint" type="revolute">
    <parent link="left_forearm_z"/>
    <child link="left_forearm_x"/>
    <axis xyz="1 0 0"/>
    <origin xyz="0 0 0" rpy="0 0 0"/>
    <limit lower="-${PI/2}" upper="${PI/2}" effort="${effort}" velocity="${velocity}"/>
  </joint>

  <!--====================== Left Hand ======================-->
   <!-- Left Palm -->
  <link name="Left_Palm">
    <visual>
      <origin xyz="1.25 -0.4 -2.5661" rpy="0 0 0"/>
      <geometry>
        <mesh filename="package://ela2_arms/meshes/Left_Palm.stl" scale="0.01 0.01 0.01"/>
      </geometry>
    </visual>
    <collision>
      <origin xyz="1.25 -0.4 -2.5661" rpy="0 0 0"/>
      <geometry>
        <box size="0.1 0.1 0.1"/>
      </geometry>
    </collision>
    <inertial>
      <origin xyz="0 0 0" rpy="0 0 0"/>
      <mass value="1.0"/>
      <inertia ixx="1" ixy="0.0" ixz="0.0" iyy="1" iyz="0.0" izz="1"/>
    </inertial>
  </link>

  <joint name="left_palm_joint" type="fixed">
    <parent link="left_forearm_x"/>
    <child link="Left_Palm"/>
    <origin xyz="0 0 0" rpy="0 0 0"/>
  </joint>

  <!-- Left Finger -->
  <link name="left_Finger">
    <visual>
      <origin xyz="1 -0.4 -0.5661" rpy="0 0 0"/>
      <geometry>
        <mesh filename="package://ela2_arms/meshes/Left_Finger.stl" scale="0.01 0.01 0.01"/>
      </geometry>
    </visual>
    <collision>
      <origin xyz="1 -0.4 -0.5661" rpy="0 0 0"/>
      <geometry>
        <box size="0.1 0.1 0.1"/>
      </geometry>
    </collision>
    <inertial>
      <origin xyz="0 0 0" rpy="0 0 0"/>
      <mass value="1.0"/>
      <inertia ixx="1" ixy="0.0" ixz="0.0" iyy="1" iyz="0.0" izz="1"/>
    </inertial>
  </link>

  <joint name="left_finger_joint" type="revolute">
    <parent link="Left_Palm"/>
    <child link="left_Finger"/>
    <axis xyz="0 1 0"/>
    <origin xyz="0.25 0 -2.04" rpy="0 0 0"/>
    <limit lower="-${0.4}" upper="${0.3}" effort="${effort}" velocity="${velocity}"/>
  </joint>

<!--====================== Right Upper Arm ======================-->
  <link name="right_upper_arm_x">
    <visual>
      <origin xyz="-1 -0.4 -4.5661" rpy="0 0 0"/>
      <geometry>
        <mesh filename="package://ela2_arms/meshes/Right_Upper_Arm.stl" scale="0.01 0.01 0.01"/>
      </geometry>
    </visual>
    <collision>
      <origin xyz="-1 -0.4 -4.5661" rpy="0 0 0"/>
      <geometry>
        <box size="0.1 0.1 0.1"/>
      </geometry>
    </collision>
    <inertial>
      <origin xyz="0 0 0" rpy="0 0 0"/>
      <mass value="1.0"/>
      <inertia ixx="1" ixy="0.0" ixz="0.0" iyy="1" iyz="0.0" izz="1"/>
    </inertial>
  </link>

  <link name="right_upper_arm_y">
    <visual>
      <origin xyz="-1 -0.4 0" rpy="0 0 0"/>
      <geometry>
        <box size="0.01 0.01 0.01"/>
      </geometry>
    </visual>
    <collision>
      <origin xyz="-1 -0.4 0" rpy="0 0 0"/>
      <geometry>
        <box size="0.1 0.1 0.1"/>
      </geometry>
    </collision>
    <inertial>
      <origin xyz="0 0 0" rpy="0 0 0"/>
      <mass value="1.0"/>
      <inertia ixx="1" ixy="0.0" ixz="0.0" iyy="1" iyz="0.0" izz="1"/>
    </inertial>
  </link>

  <joint name="right_upper_arm_y_joint" type="revolute">
    <parent link="chest"/>
    <child link="right_upper_arm_y"/>
    <axis xyz="0 1 0"/>
    <origin xyz="1.04 0.4 0" rpy="0 0 0"/>
    <limit lower="-${PI/2}" upper="${0}" effort="${effort}" velocity="${velocity}"/>
  </joint>

  <joint name="right_upper_arm_x_joint" type="revolute">
    <parent link="right_upper_arm_y"/>
    <child link="right_upper_arm_x"/>
    <axis xyz="1 0 0"/>
    <origin xyz="0 0 0" rpy="0 0 0"/>
    <limit lower="-${1.197}" upper="${0.704}" effort="${effort}" velocity="${velocity}"/>
  </joint>

  <!--====================== Right Forearm ======================-->
  <link name="right_forearm_x">
    <visual>
      <origin xyz="-1.25 -0.4 -2.5661" rpy="0 0 0"/>
      <geometry>
        <mesh filename="package://ela2_arms/meshes/Right_Forearm.stl" scale="0.01 0.01 0.01"/>
      </geometry>
    </visual>
    <collision>
      <origin xyz="-1.25 -0.4 -2.5661" rpy="0 0 0"/>
      <geometry>
        <box size="0.1 0.1 0.1"/>
      </geometry>
    </collision>
    <inertial>
      <origin xyz="0 0 0" rpy="0 0 0"/>
      <mass value="1.0"/>
      <inertia ixx="1" ixy="0.0" ixz="0.0" iyy="1" iyz="0.0" izz="1"/>
    </inertial>
  </link>

  <link name="right_forearm_z">
    <visual>
      <origin xyz="0 0 0" rpy="0 0 0"/>
      <geometry>
        <box size="0.01 0.01 0.01"/>
      </geometry>
    </visual>
    <collision>
      <origin xyz="0 0 0" rpy="0 0 0"/>
      <geometry>
        <box size="0.1 0.1 0.1"/>
      </geometry>
    </collision>
    <inertial>
      <origin xyz="0 0 0" rpy="0 0 0"/>
      <mass value="1.0"/>
      <inertia ixx="1" ixy="0.0" ixz="0.0" iyy="1" iyz="0.0" izz="1"/>
    </inertial>
  </link>

  <joint name="right_forearm_z_joint" type="revolute">
    <parent link="right_upper_arm_x"/>
    <child link="right_forearm_z"/>
    <axis xyz="0 0 1"/>
    <origin xyz="0.25 -0.04 -2" rpy="0 0 0"/>
    <limit lower="-${PI/2}" upper="${PI/2}" effort="${effort}" velocity="${velocity}"/>
  </joint>

  <joint name="right_forearm_x_joint" type="revolute">
    <parent link="right_forearm_z"/>
    <child link="right_forearm_x"/>
    <axis xyz="1 0 0"/>
    <origin xyz="0 0 0" rpy="0 0 0"/>
    <limit lower="-${PI/2}" upper="${PI/2}" effort="${effort}" velocity="${velocity}"/>
  </joint>

  <!--====================== Right Hand ======================-->
   <!-- ight Palm -->
  <link name="Right_Palm">
    <visual>
      <origin xyz="-1.25 -0.4 -2.5661" rpy="0 0 0"/>
      <geometry>
        <mesh filename="package://ela2_arms/meshes/Right_Palm.stl" scale="0.01 0.01 0.01"/>
      </geometry>
    </visual>
    <collision>
      <origin xyz="-1.25 -0.4 -2.5661" rpy="0 0 0"/>
      <geometry>
        <box size="0.1 0.1 0.1"/>
      </geometry>
    </collision>
    <inertial>
      <origin xyz="0 0 0" rpy="0 0 0"/>
      <mass value="1.0"/>
      <inertia ixx="1" ixy="0.0" ixz="0.0" iyy="1" iyz="0.0" izz="1"/>
    </inertial>
  </link>

  <joint name="right_palm_joint" type="fixed">
    <parent link="right_forearm_x"/>
    <child link="Right_Palm"/>
    <origin xyz="0 0 0" rpy="0 0 0"/>
  </joint>

  <!-- Right Finger -->
  <link name="right_Finger">
    <visual>
      <origin xyz="-1 -0.4 -0.5661" rpy="0 0 0"/>
      <geometry>
        <mesh filename="package://ela2_arms/meshes/Right_Finger.stl" scale="0.01 0.01 0.01"/>
      </geometry>
    </visual>
    <collision>
      <origin xyz="-1 -0.4 -0.5661" rpy="0 0 0"/>
      <geometry>
        <box size="0.1 0.1 0.1"/>
      </geometry>
    </collision>
    <inertial>
      <origin xyz="0 0 0" rpy="0 0 0"/>
      <mass value="1.0"/>
      <inertia ixx="1" ixy="0.0" ixz="0.0" iyy="1" iyz="0.0" izz="1"/>
    </inertial>
  </link>

  <joint name="right_finger_joint" type="revolute">
    <parent link="Right_Palm"/>
    <child link="right_Finger"/>
    <axis xyz="0 1 0"/>
    <origin xyz="-0.25 0 -2.04" rpy="0 0 0"/>
    <limit lower="-${0.4}" upper="${0.3}" effort="${effort}" velocity="${velocity}"/>
  </joint>




  <xacro:default_transmission number="1" joint_name="left_upper_arm_y_joint"/>
  <xacro:default_transmission number="2" joint_name="left_upper_arm_x_joint"/>
  <xacro:default_transmission number="3" joint_name="left_forearm_z_joint"/>
  <xacro:default_transmission number="4" joint_name="left_forearm_x_joint"/>
  <xacro:default_transmission number="5" joint_name="left_finger_joint"/>
  <xacro:default_transmission number="6" joint_name="right_upper_arm_y_joint"/>
  <xacro:default_transmission number="7" joint_name="right_upper_arm_x_joint"/>
  <xacro:default_transmission number="8" joint_name="right_forearm_z_joint"/>
  <xacro:default_transmission number="9" joint_name="right_forearm_x_joint"/>
  <xacro:default_transmission number="10" joint_name="right_finger_joint"/>






</robot>
